Workbook
Name Slicer_Designation: #N/A
Name Slicer_Quarter_of_Joining_Date: #N/A
Name Slicer_Team: #N/A
Name Slicer_Team1: #N/A
Name Slicer_Type: #N/A
Name Slicer_Year_of_Joining_Date: #N/A

Sheet Resource
A1: Employee ID | B1: Corrected Employee ID | C1: Employee Name | D1: Employee First Working Day | E1: Corrected Employee First Working Day | F1: Designation | G1: Team | H1: Type | I1: Assigned Project 1 Code | J1: Assigned Project 2 Code | K1: Assigned Project 3 Code | L1: Year of Joining Date | M1: Quarter of Joining Date | N1: Quarter & Year of Joining Date
A2: EMP-001 | B2: ="emp"&TEXT(VALUE(SUBSTITUTE(SUBSTITUTE(UPPER(TRIM(A2)),"EMP",""),"-","")),"000") -> emp001 | C2: Rohit Sharma | D2: 44562 | E2: =IF(D2="","", IF(ISNUMBER(D2),D2, IFERROR(DATEVALUE(D2), IFERROR(DATEVALUE(SUBSTITUTE(SUBSTITUTE(SUBSTITUTE(LOWER(D2),"th",""),".","/"),"-","/")),"Check")))) -> 44562 | F2: Sr. Consultant | G2: Data | H2: FTE | I2: PRJ-020 | J2: PRJ-065 | L2: =IF(E2="","Missing",YEAR(E2)) -> 2022 | M2: =IF(E2="","Missing","Q"&ROUNDUP(MONTH(E2)/3,0)) -> Q1 | N2: =YEAR(E2)&"-Q"&ROUNDUP(MONTH(E2)/3,0) -> 2022-Q1
A3: emp002 | B3: ="emp"&TEXT(VALUE(SUBSTITUTE(SUBSTITUTE(UPPER(TRIM(A3)),"EMP",""),"-","")),"000") -> emp002 | C3: Anjali Verma | D3: 44242 | E3: =IF(D3="","", IF(ISNUMBER(D3),D3, IFERROR(DATEVALUE(D3), IFERROR(DATEVALUE(SUBSTITUTE(SUBSTITUTE(SUBSTITUTE(LOWER(D3),"th",""),".","/"),"-","/")),"Check")))) -> 44242 | F3: Manager | G3: Digital | H3: FTE | I3: PRJ-029 | J3: PRJ-070 | L3: =IF(E3="","Missing",YEAR(E3)) -> 2021 | M3: =IF(E3="","Missing","Q"&ROUNDUP(MONTH(E3)/3,0)) -> Q1 | N3: =YEAR(E3)&"-Q"&ROUNDUP(MONTH(E3)/3,0) -> 2021-Q1
A4: EMP 003 | B4: ="emp"&TEXT(VALUE(SUBSTITUTE(SUBSTITUTE(UPPER(TRIM(A4)),"EMP",""),"-","")),"000") -> emp003 | C4: Suresh Iyer | D4: 44022 | E4: =IF(D4="","", IF(ISNUMBER(D4),D4, IFERROR(DATEVALUE(D4), IFERROR(DATEVALUE(SUBSTITUTE(SUBSTITUTE(SUBSTITUTE(LOWER(D4),"th",""),".","/"),"-","/")),"Check")))) -> 44022 | F4: Lead Consultant | G4: AI | H4: FTE | I4: PRJ-007 | J4: PRJ-056 | L4: =IF(E4="","Missing",YEAR(E4)) -> 2020 | M4: =IF(E4="","Missing","Q"&ROUNDUP(MONTH(E4)/3,0)) -> Q3 | N4: =YEAR(E4)&"-Q"&ROUNDUP(MONTH(E4)/3,0) -> 2020-Q3
A5: EMP-004 | B5: ="emp"&TEXT(VALUE(SUBSTITUTE(SUBSTITUTE(UPPER(TRIM(A5)),"EMP",""),"-","")),"000") -> emp004 | C5: Megha Jain | D5: 03-15-2019 | E5: =IF(D5="","", IF(ISNUMBER(D5),D5, IFERROR(DATEVALUE(D5), IFERROR(DATEVALUE(SUBSTITUTE(SUBSTITUTE(SUBSTITUTE(LOWER(D5),"th",""),".","/"),"-","/")),"Check")))) -> 43539 | F5: Consultant | G5: Digital | H5: FTE | I5: PRJ-040 | J5: PRJ-053 | L5: =IF(E5="","Missing",YEAR(E5)) -> 2019 | M5: =IF(E5="","Missing","Q"&ROUNDUP(MONTH(E5)/3,0)) -> Q1 | N5: =YEAR(E5)&"-Q"&ROUNDUP(MONTH(E5)/3,0) -> 2019-Q1
A6: EMP005 | B6: ="emp"&TEXT(VALUE(SUBSTITUTE(SUBSTITUTE(UPPER(TRIM(A6)),"EMP",""),"-","")),"000") -> emp005 | C6: Neha Malhotra | D6: 45017 | E6: =IF(D6="","", IF(ISNUMBER(D6),D6, IFERROR(DATEVALUE(D6), IFERROR(DATEVALUE(SUBSTITUTE(SUBSTITUTE(SUBSTITUTE(LOWER(D6),"th",""),".","/"),"-","/")),"Check")))) -> 45017 | F6: Senior Consultant | G6: Data | H6: FTE | I6: PRJ-012 | J6: PRJ-067 | K6: PRJ-085 | L6: =IF(E6="","Missing",YEAR(E6)) -> 2023 | M6: =IF(E6="","Missing","Q"&ROUNDUP(MONTH(E6)/3,0)) -> Q2 | N6: =YEAR(E6)&"-Q"&ROUNDUP(MONTH(E6)/3,0) -> 2023-Q2
A7: EMP-006 | B7: ="emp"&TEXT(VALUE(SUBSTITUTE(SUBSTITUTE(UPPER(TRIM(A7)),"EMP",""),"-","")),"000") -> emp006 | C7: Rahul Mehta | D7: 43405 | E7: =IF(D7="","", IF(ISNUMBER(D7),D7, IFERROR(DATEVALUE(D7), IFERROR(DATEVALUE(SUBSTITUTE(SUBSTITUTE(SUBSTITUTE(LOWER(D7),"th",""),".","/"),"-","/")),"Check")))) -> 43405 | F7: Principal Consultant | G7: AI | H7: FTE | I7: PRJ-011 | J7: PRJ-065 | L7: =IF(E7="","Missing",YEAR(E7)) -> 2018 | M7: =IF(E7="","Missing","Q"&ROUNDUP(MONTH(E7)/3,0)) -> Q4 | N7: =YEAR(E7)&"-Q"&ROUNDUP(MONTH(E7)/3,0) -> 2018-Q4
A8: emp-007 | B8: ="emp"&TEXT(VALUE(SUBSTITUTE(SUBSTITUTE(UPPER(TRIM(A8)),"EMP",""),"-","")),"000") -> emp007 | C8: Priya Nair | D8: 42898 | E8: =IF(D8="","", IF(ISNUMBER(D8),D8, IFERROR(DATEVALUE(D8), IFERROR(DATEVALUE(SUBSTITUTE(SUBSTITUTE(SUBSTITUTE(LOWER(D8),"th",""),".","/"),"-","/")),"Check")))) -> 42898 | F8: Consultant | G8: Digital | H8: FTE | I8: PRJ-023 | L8: =IF(E8="","Missing",YEAR(E8)) -> 2017 | M8: =IF(E8="","Missing","Q"&ROUNDUP(MONTH(E8)/3,0)) -> Q2 | N8: =YEAR(E8)&"-Q"&ROUNDUP(MONTH(E8)/3,0) -> 2017-Q2
A9: EMP008 | B9: ="emp"&TEXT(VALUE(SUBSTITUTE(SUBSTITUTE(UPPER(TRIM(A9)),"EMP",""),"-","")),"000") -> emp008 | C9: Vikram Singh | D9: 07.08.2020 | E9: =IF(D9="","", IF(ISNUMBER(D9),D9, IFERROR(DATEVALUE(D9), IFERROR(DATEVALUE(SUBSTITUTE(SUBSTITUTE(SUBSTITUTE(LOWER(D9),"th",""),".","/"),"-","/")),"Check")))) -> 44020 | F9: Consultant | G9: Data | H9: FTE | I9: PRJ-013 | J9: PRJ-051 | L9: =IF(E9="","Missing",YEAR(E9)) -> 2020 | M9: =IF(E9="","Missing","Q"&ROUNDUP(MONTH(E9)/3,0)) -> Q3 | N9: =YEAR(E9)&"-Q"&ROUNDUP(MONTH(E9)/3,0) -> 2020-Q3
A10: EMP-009 | B10: ="emp"&TEXT(VALUE(SUBSTITUTE(SUBSTITUTE(UPPER(TRIM(A10)),"EMP",""),"-","")),"000") -> emp009 | C10: Karan Ahuja | D10: 44571 | E10: =IF(D10="","", IF(ISNUMBER(D10),D10, IFERROR(DATEVALUE(D10), IFERROR(DATEVALUE(SUBSTITUTE(SUBSTITUTE(SUBSTITUTE(LOWER(D10),"th",""),".","/"),"-","/")),"Check")))) -> 44571 | F10: Analyst | G10: Data | H10: Intern | I10: PRJ-004 | L10: =IF(E10="","Missing",YEAR(E10)) -> 2022 | M10: =IF(E10="","Missing","Q"&ROUNDUP(MONTH(E10)/3,0)) -> Q1 | N10: =YEAR(E10)&"-Q"&ROUNDUP(MONTH(E10)/3,0) -> 2022-Q1
A11: EMP-010 | B11: ="emp"&TEXT(VALUE(SUBSTITUTE(SUBSTITUTE(UPPER(TRIM(A11)),"EMP",""),"-","")),"000") -> emp010 | C11: Pooja Kulkarni | D11: 45673 | E11: =IF(D11="","", IF(ISNUMBER(D11),D11, IFERROR(DATEVALUE(D11), IFERROR(DATEVALUE(SUBSTITUTE(SUBSTITUTE(SUBSTITUTE(LOWER(D11),"th",""),".","/"),"-","/")),"Check")))) -> 45673 | F11: Consultant | G11: AI | H11: Intern | I11: PRJ-030 | L11: =IF(E11="","Missing",YEAR(E11)) -> 2025 | M11: =IF(E11="","Missing","Q"&ROUNDUP(MONTH(E11)/3,0)) -> Q1 | N11: =YEAR(E11)&"-Q"&ROUNDUP(MONTH(E11)/3,0) -> 2025-Q1
A12: EMP011 | B12: ="emp"&TEXT(VALUE(SUBSTITUTE(SUBSTITUTE(UPPER(TRIM(A12)),"EMP",""),"-","")),"000") -> emp011 | C12: Aman Gupta | D12: 43713 | E12: =IF(D12="","", IF(ISNUMBER(D12),D12, IFERROR(DATEVALUE(D12), IFERROR(DATEVALUE(SUBSTITUTE(SUBSTITUTE(SUBSTITUTE(LOWER(D12),"th",""),".","/"),"-","/")),"Check")))) -> 43713 | F12: Consultant | G12: Digital | H12: FTE | I12: PRJ-045 | J12: PRJ-060 | L12: =IF(E12="","Missing",YEAR(E12)) -> 2019 | M12: =IF(E12="","Missing","Q"&ROUNDUP(MONTH(E12)/3,0)) -> Q3 | N12: =YEAR(E12)&"-Q"&ROUNDUP(MONTH(E12)/3,0) -> 2019-Q3
A13: EMP-012 | B13: ="emp"&TEXT(VALUE(SUBSTITUTE(SUBSTITUTE(UPPER(TRIM(A13)),"EMP",""),"-","")),"000") -> emp012 | C13: Sneha Rao | D13: 44260 | E13: =IF(D13="","", IF(ISNUMBER(D13),D13, IFERROR(DATEVALUE(D13), IFERROR(DATEVALUE(SUBSTITUTE(SUBSTITUTE(SUBSTITUTE(LOWER(D13),"th",""),".","/"),"-","/")),"Check")))) -> 44260 | F13: Analyst | G13: Data | H13: Intern | I13: PRJ-033 | L13: =IF(E13="","Missing",YEAR(E13)) -> 2021 | M13: =IF(E13="","Missing","Q"&ROUNDUP(MONTH(E13)/3,0)) -> Q1 | N13: =YEAR(E13)&"-Q"&ROUNDUP(MONTH(E13)/3,0) -> 2021-Q1
A14: emp013 | B14: ="emp"&TEXT(VALUE(SUBSTITUTE(SUBSTITUTE(UPPER(TRIM(A14)),"EMP",""),"-","")),"000") -> emp013 | C14: Rakesh Kumar | D14: 45301 | E14: =IF(D14="","", IF(ISNUMBER(D14),D14, IFERROR(DATEVALUE(D14), IFERROR(DATEVALUE(SUBSTITUTE(SUBSTITUTE(SUBSTITUTE(LOWER(D14),"th",""),".","/"),"-","/")),"Check")))) -> 45301 | F14: Sr. Consultant | G14: AI | H14: FTE | I14: PRJ-016 | J14: PRJ-060 | L14: =IF(E14="","Missing",YEAR(E14)) -> 2024 | M14: =IF(E14="","Missing","Q"&ROUNDUP(MONTH(E14)/3,0)) -> Q1 | N14: =YEAR(E14)&"-Q"&ROUNDUP(MONTH(E14)/3,0) -> 2024-Q1
A15: EMP 014 | B15: ="emp"&TEXT(VALUE(SUBSTITUTE(SUBSTITUTE(UPPER(TRIM(A15)),"EMP",""),"-","")),"000") -> emp014 | C15: Kavita Joshi | D15: 42780 | E15: =IF(D15="","", IF(ISNUMBER(D15),D15, IFERROR(DATEVALUE(D15), IFERROR(DATEVALUE(SUBSTITUTE(SUBSTITUTE(SUBSTITUTE(LOWER(D15),"th",""),".","/"),"-","/")),"Check")))) -> 42780 | F15: Consultant | G15: Digital | H15: FTE | I15: PRJ-005 | J15: PRJ-080 | L15: =IF(E15="","Missing",YEAR(E15)) -> 2017 | M15: =IF(E15="","Missing","Q"&ROUNDUP(MONTH(E15)/3,0)) -> Q1 | N15: =YEAR(E15)&"-Q"&ROUNDUP(MONTH(E15)/3,0) -> 2017-Q1
A16: EMP-015 | B16: ="emp"&TEXT(VALUE(SUBSTITUTE(SUBSTITUTE(UPPER(TRIM(A16)),"EMP",""),"-","")),"000") -> emp015 | C16: Nitin Arora | D16: 01.06.2020 | E16: =IF(D16="","", IF(ISNUMBER(D16),D16, IFERROR(DATEVALUE(D16), IFERROR(DATEVALUE(SUBSTITUTE(SUBSTITUTE(SUBSTITUTE(LOWER(D16),"th",""),".","/"),"-","/")),"Check")))) -> 43836 | F16: Lead Consultant | G16: Data | H16: FTE | I16: PRJ-004 | J16: PRJ-076 | K16: PRJ-078 | L16: =IF(E16="","Missing",YEAR(E16)) -> 2020 | M16: =IF(E16="","Missing","Q"&ROUNDUP(MONTH(E16)/3,0)) -> Q1 | N16: =YEAR(E16)&"-Q"&ROUNDUP(MONTH(E16)/3,0) -> 2020-Q1
A17: emp016 | B17: ="emp"&TEXT(VALUE(SUBSTITUTE(SUBSTITUTE(UPPER(TRIM(A17)),"EMP",""),"-","")),"000") -> emp016 | C17: Pankaj Mishra | D17: 42705 | E17: =IF(D17="","", IF(ISNUMBER(D17),D17, IFERROR(DATEVALUE(D17), IFERROR(DATEVALUE(SUBSTITUTE(SUBSTITUTE(SUBSTITUTE(LOWER(D17),"th",""),".","/"),"-","/")),"Check")))) -> 42705 | F17: Analyst | G17: AI | H17: FTE | I17: PRJ-016 | J17: PRJ-070 | L17: =IF(E17="","Missing",YEAR(E17)) -> 2016 | M17: =IF(E17="","Missing","Q"&ROUNDUP(MONTH(E17)/3,0)) -> Q4 | N17: =YEAR(E17)&"-Q"&ROUNDUP(MONTH(E17)/3,0) -> 2016-Q4
A18: EMP-017 | B18: ="emp"&TEXT(VALUE(SUBSTITUTE(SUBSTITUTE(UPPER(TRIM(A18)),"EMP",""),"-","")),"000") -> emp017 | C18: Swati Kulkarni | D18: 44423 | E18: =IF(D18="","", IF(ISNUMBER(D18),D18, IFERROR(DATEVALUE(D18), IFERROR(DATEVALUE(SUBSTITUTE(SUBSTITUTE(SUBSTITUTE(LOWER(D18),"th",""),".","/"),"-","/")),"Check")))) -> 44423 | F18: Consultant | G18: Digital | H18: FTE | I18: PRJ-001 | J18: PRJ-053 | L18: =IF(E18="","Missing",YEAR(E18)) -> 2021 | M18: =IF(E18="","Missing","Q"&ROUNDUP(MONTH(E18)/3,0)) -> Q3 | N18: =YEAR(E18)&"-Q"&ROUNDUP(MONTH(E18)/3,0) -> 2021-Q3
A19: EMP018 | B19: ="emp"&TEXT(VALUE(SUBSTITUTE(SUBSTITUTE(UPPER(TRIM(A19)),"EMP",""),"-","")),"000") -> emp018 | C19: Arjun Mehta | D19: 44621 | E19: =IF(D19="","", IF(ISNUMBER(D19),D19, IFERROR(DATEVALUE(D19), IFERROR(DATEVALUE(SUBSTITUTE(SUBSTITUTE(SUBSTITUTE(LOWER(D19),"th",""),".","/"),"-","/")),"Check")))) -> 44621 | F19: Analyst | G19: Data | H19: Intern | I19: PRJ-028 | L19: =IF(E19="","Missing",YEAR(E19)) -> 2022 | M19: =IF(E19="","Missing","Q"&ROUNDUP(MONTH(E19)/3,0)) -> Q1 | N19: =YEAR(E19)&"-Q"&ROUNDUP(MONTH(E19)/3,0) -> 2022-Q1
A20: EMP-019 | B20: ="emp"&TEXT(VALUE(SUBSTITUTE(SUBSTITUTE(UPPER(TRIM(A20)),"EMP",""),"-","")),"000") -> emp019 | C20: Isha Kapoor | D20: 44123 | E20: =IF(D20="","", IF(ISNUMBER(D20),D20, IFERROR(DATEVALUE(D20), IFERROR(DATEVALUE(SUBSTITUTE(SUBSTITUTE(SUBSTITUTE(LOWER(D20),"th",""),".","/"),"-","/")),"Check")))) -> 44123 | F20: Consultant | G20: AI | H20: FTE | I20: PRJ-007 | J20: PRJ-051 | L20: =IF(E20="","Missing",YEAR(E20)) -> 2020 | M20: =IF(E20="","Missing","Q"&ROUNDUP(MONTH(E20)/3,0)) -> Q4 | N20: =YEAR(E20)&"-Q"&ROUNDUP(MONTH(E20)/3,0) -> 2020-Q4
A21: EMP020 | B21: ="emp"&TEXT(VALUE(SUBSTITUTE(SUBSTITUTE(UPPER(TRIM(A21)),"EMP",""),"-","")),"000") -> emp020 | C21: Mohit Bansal | D21: 43668 | E21: =IF(D21="","", IF(ISNUMBER(D21),D21, IFERROR(DATEVALUE(D21), IFERROR(DATEVALUE(SUBSTITUTE(SUBSTITUTE(SUBSTITUTE(LOWER(D21),"th",""),".","/"),"-","/")),"Check")))) -> 43668 | F21: Senior Consultant | G21: Digital | H21: FTE | I21: PRJ-025 | J21: PRJ-063 | K21: PRJ-084 | L21: =IF(E21="","Missing",YEAR(E21)) -> 2019 | M21: =IF(E21="","Missing","Q"&ROUNDUP(MONTH(E21)/3,0)) -> Q3 | N21: =YEAR(E21)&"-Q"&ROUNDUP(MONTH(E21)/3,0) -> 2019-Q3
A22: emp021 | B22: ="emp"&TEXT(VALUE(SUBSTITUTE(SUBSTITUTE(UPPER(TRIM(A22)),"EMP",""),"-","")),"000") -> emp021 | C22: Nisha Jain | D22: 44207 | E22: =IF(D22="","", IF(ISNUMBER(D22),D22, IFERROR(DATEVALUE(D22), IFERROR(DATEVALUE(SUBSTITUTE(SUBSTITUTE(SUBSTITUTE(LOWER(D22),"th",""),".","/"),"-","/")),"Check")))) -> 44207 | F22: Analyst | G22: Data | H22: Intern | I22: PRJ-020 | L22: =IF(E22="","Missing",YEAR(E22)) -> 2021 | M22: =IF(E22="","Missing","Q"&ROUNDUP(MONTH(E22)/3,0)) -> Q1 | N22: =YEAR(E22)&"-Q"&ROUNDUP(MONTH(E22)/3,0) -> 2021-Q1
A23: EMP-022 | B23: ="emp"&TEXT(VALUE(SUBSTITUTE(SUBSTITUTE(UPPER(TRIM(A23)),"EMP",""),"-","")),"000") -> emp022 | C23: Varun Malhotra | D23: 2018.04.03 | E23: =IF(D23="","", IF(ISNUMBER(D23),D23, IFERROR(DATEVALUE(D23), IFERROR(DATEVALUE(SUBSTITUTE(SUBSTITUTE(SUBSTITUTE(LOWER(D23),"th",""),".","/"),"-","/")),"Check")))) -> 43193 | F23: Consultant | G23: AI | H23: FTE | I23: PRJ-036 | J23: PRJ-081 | L23: =IF(E23="","Missing",YEAR(E23)) -> 2018 | M23: =IF(E23="","Missing","Q"&ROUNDUP(MONTH(E23)/3,0)) -> Q2 | N23: =YEAR(E23)&"-Q"&ROUNDUP(MONTH(E23)/3,0) -> 2018-Q2
A24: EMP 023 | B24: ="emp"&TEXT(VALUE(SUBSTITUTE(SUBSTITUTE(UPPER(TRIM(A24)),"EMP",""),"-","")),"000") -> emp023 | C24: Ritu Saxena | D24: 42884 | E24: =IF(D24="","", IF(ISNUMBER(D24),D24, IFERROR(DATEVALUE(D24), IFERROR(DATEVALUE(SUBSTITUTE(SUBSTITUTE(SUBSTITUTE(LOWER(D24),"th",""),".","/"),"-","/")),"Check")))) -> 42884 | F24: Lead Consultant | G24: Digital | H24: FTE | I24: PRJ-010 | J24: PRJ-074 | L24: =IF(E24="","Missing",YEAR(E24)) -> 2017 | M24: =IF(E24="","Missing","Q"&ROUNDUP(MONTH(E24)/3,0)) -> Q2 | N24: =YEAR(E24)&"-Q"&ROUNDUP(MONTH(E24)/3,0) -> 2017-Q2
A25: EMP-024 | B25: ="emp"&TEXT(VALUE(SUBSTITUTE(SUBSTITUTE(UPPER(TRIM(A25)),"EMP",""),"-","")),"000") -> emp024 | C25: Akash Verma | D25: 44805 | E25: =IF(D25="","", IF(ISNUMBER(D25),D25, IFERROR(DATEVALUE(D25), IFERROR(DATEVALUE(SUBSTITUTE(SUBSTITUTE(SUBSTITUTE(LOWER(D25),"th",""),".","/"),"-","/")),"Check")))) -> 44805 | F25: Analyst | G25: Data | H25: FTE | I25: PRJ-023 | J25: PRJ-061 | L25: =IF(E25="","Missing",YEAR(E25)) -> 2022 | M25: =IF(E25="","Missing","Q"&ROUNDUP(MONTH(E25)/3,0)) -> Q3 | N25: =YEAR(E25)&"-Q"&ROUNDUP(MONTH(E25)/3,0) -> 2022-Q3
A26: EMP025 | B26: ="emp"&TEXT(VALUE(SUBSTITUTE(SUBSTITUTE(UPPER(TRIM(A26)),"EMP",""),"-","")),"000") -> emp025 | C26: Pooja Shah | D26: 43878 | E26: =IF(D26="","", IF(ISNUMBER(D26),D26, IFERROR(DATEVALUE(D26), IFERROR(DATEVALUE(SUBSTITUTE(SUBSTITUTE(SUBSTITUTE(LOWER(D26),"th",""),".","/"),"-","/")),"Check")))) -> 43878 | F26: Consultant | G26: AI | H26: FTE | I26: PRJ-002 | J26: PRJ-070 | L26: =IF(E26="","Missing",YEAR(E26)) -> 2020 | M26: =IF(E26="","Missing","Q"&ROUNDUP(MONTH(E26)/3,0)) -> Q1 | N26: =YEAR(E26)&"-Q"&ROUNDUP(MONTH(E26)/3,0) -> 2020-Q1
A27: emp026 | B27: ="emp"&TEXT(VALUE(SUBSTITUTE(SUBSTITUTE(UPPER(TRIM(A27)),"EMP",""),"-","")),"000") -> emp026 | C27: Kunal Desai | D27: 42439 | E27: =IF(D27="","", IF(ISNUMBER(D27),D27, IFERROR(DATEVALUE(D27), IFERROR(DATEVALUE(SUBSTITUTE(SUBSTITUTE(SUBSTITUTE(LOWER(D27),"th",""),".","/"),"-","/")),"Check")))) -> 42439 | F27: Senior Consultant | G27: Digital | H27: Freelancer | I27: PRJ-013 | L27: =IF(E27="","Missing",YEAR(E27)) -> 2016 | M27: =IF(E27="","Missing","Q"&ROUNDUP(MONTH(E27)/3,0)) -> Q1 | N27: =YEAR(E27)&"-Q"&ROUNDUP(MONTH(E27)/3,0) -> 2016-Q1
A28: EMP-027 | B28: ="emp"&TEXT(VALUE(SUBSTITUTE(SUBSTITUTE(UPPER(TRIM(A28)),"EMP",""),"-","")),"000") -> emp027 | C28: Aditi Chawla | D28: 43777 | E28: =IF(D28="","", IF(ISNUMBER(D28),D28, IFERROR(DATEVALUE(D28), IFERROR(DATEVALUE(SUBSTITUTE(SUBSTITUTE(SUBSTITUTE(LOWER(D28),"th",""),".","/"),"-","/")),"Check")))) -> 43777 | F28: Consultant | G28: Data | H28: FTE | I28: PRJ-007 | J28: PRJ-055 | L28: =IF(E28="","Missing",YEAR(E28)) -> 2019 | M28: =IF(E28="","Missing","Q"&ROUNDUP(MONTH(E28)/3,0)) -> Q4 | N28: =YEAR(E28)&"-Q"&ROUNDUP(MONTH(E28)/3,0) -> 2019-Q4
A29: EMP028 | B29: ="emp"&TEXT(VALUE(SUBSTITUTE(SUBSTITUTE(UPPER(TRIM(A29)),"EMP",""),"-","")),"000") -> emp028 | C29: Sarthak Jain | D29: 44361 | E29: =IF(D29="","", IF(ISNUMBER(D29),D29, IFERROR(DATEVALUE(D29), IFERROR(DATEVALUE(SUBSTITUTE(SUBSTITUTE(SUBSTITUTE(LOWER(D29),"th",""),".","/"),"-","/")),"Check")))) -> 44361 | F29: Analyst | G29: AI | H29: Intern | I29: PRJ-036 | J29: PRJ-086 | L29: =IF(E29="","Missing",YEAR(E29)) -> 2021 | M29: =IF(E29="","Missing","Q"&ROUNDUP(MONTH(E29)/3,0)) -> Q2 | N29: =YEAR(E29)&"-Q"&ROUNDUP(MONTH(E29)/3,0) -> 2021-Q2
A30: EMP-029 | B30: ="emp"&TEXT(VALUE(SUBSTITUTE(SUBSTITUTE(UPPER(TRIM(A30)),"EMP",""),"-","")),"000") -> emp029 | C30: Manish Gupta | D30: 43333 | E30: =IF(D30="","", IF(ISNUMBER(D30),D30, IFERROR(DATEVALUE(D30), IFERROR(DATEVALUE(SUBSTITUTE(SUBSTITUTE(SUBSTITUTE(LOWER(D30),"th",""),".","/"),"-","/")),"Check")))) -> 43333 | F30: Lead Consultant | G30: Digital | H30: FTE | I30: PRJ-015 | J30: PRJ-063 | L30: =IF(E30="","Missing",YEAR(E30)) -> 2018 | M30: =IF(E30="","Missing","Q"&ROUNDUP(MONTH(E30)/3,0)) -> Q3 | N30: =YEAR(E30)&"-Q"&ROUNDUP(MONTH(E30)/3,0) -> 2018-Q3
A31: EMP030 | B31: ="emp"&TEXT(VALUE(SUBSTITUTE(SUBSTITUTE(UPPER(TRIM(A31)),"EMP",""),"-","")),"000") -> emp030 | C31: Riya Khanna | D31: 44900 | E31: =IF(D31="","", IF(ISNUMBER(D31),D31, IFERROR(DATEVALUE(D31), IFERROR(DATEVALUE(SUBSTITUTE(SUBSTITUTE(SUBSTITUTE(LOWER(D31),"th",""),".","/"),"-","/")),"Check")))) -> 44900 | F31: Analyst | G31: Data | H31: Intern | I31: PRJ-021 | L31: =IF(E31="","Missing",YEAR(E31)) -> 2022 | M31: =IF(E31="","Missing","Q"&ROUNDUP(MONTH(E31)/3,0)) -> Q4 | N31: =YEAR(E31)&"-Q"&ROUNDUP(MONTH(E31)/3,0) -> 2022-Q4
A32: emp031 | B32: ="emp"&TEXT(VALUE(SUBSTITUTE(SUBSTITUTE(UPPER(TRIM(A32)),"EMP",""),"-","")),"000") -> emp031 | C32: Deepak Yadav | D32: 42843 | E32: =IF(D32="","", IF(ISNUMBER(D32),D32, IFERROR(DATEVALUE(D32), IFERROR(DATEVALUE(SUBSTITUTE(SUBSTITUTE(SUBSTITUTE(LOWER(D32),"th",""),".","/"),"-","/")),"Check")))) -> 42843 | F32: Consultant | G32: AI | H32: Freelancer | I32: PRJ-011 | J32: PRJ-076 | L32: =IF(E32="","Missing",YEAR(E32)) -> 2017 | M32: =IF(E32="","Missing","Q"&ROUNDUP(MONTH(E32)/3,0)) -> Q2 | N32: =YEAR(E32)&"-Q"&ROUNDUP(MONTH(E32)/3,0) -> 2017-Q2
A33: EMP-032 | B33: ="emp"&TEXT(VALUE(SUBSTITUTE(SUBSTITUTE(UPPER(TRIM(A33)),"EMP",""),"-","")),"000") -> emp032 | C33: Shalini Mehra | D33: 43492 | E33: =IF(D33="","", IF(ISNUMBER(D33),D33, IFERROR(DATEVALUE(D33), IFERROR(DATEVALUE(SUBSTITUTE(SUBSTITUTE(SUBSTITUTE(LOWER(D33),"th",""),".","/"),"-","/")),"Check")))) -> 43492 | F33: Senior Consultant | G33: Digital | H33: FTE | I33: PRJ-050 | J33: PRJ-058 | L33: =IF(E33="","Missing",YEAR(E33)) -> 2019 | M33: =IF(E33="","Missing","Q"&ROUNDUP(MONTH(E33)/3,0)) -> Q1 | N33: =YEAR(E33)&"-Q"&ROUNDUP(MONTH(E33)/3,0) -> 2019-Q1
A34: EMP 033 | B34: ="emp"&TEXT(VALUE(SUBSTITUTE(SUBSTITUTE(UPPER(TRIM(A34)),"EMP",""),"-","")),"000") -> emp033 | C34: Vikas Pandey | D34: 2016.06.09 | E34: =IF(D34="","", IF(ISNUMBER(D34),D34, IFERROR(DATEVALUE(D34), IFERROR(DATEVALUE(SUBSTITUTE(SUBSTITUTE(SUBSTITUTE(LOWER(D34),"th",""),".","/"),"-","/")),"Check")))) -> 42530 | F34: Consultant | G34: Data | H34: Freelancer | I34: PRJ-012 | L34: =IF(E34="","Missing",YEAR(E34)) -> 2016 | M34: =IF(E34="","Missing","Q"&ROUNDUP(MONTH(E34)/3,0)) -> Q2 | N34: =YEAR(E34)&"-Q"&ROUNDUP(MONTH(E34)/3,0) -> 2016-Q2
A35: EMP-034 | B35: ="emp"&TEXT(VALUE(SUBSTITUTE(SUBSTITUTE(UPPER(TRIM(A35)),"EMP",""),"-","")),"000") -> emp034 | C35: Tanya Arora | D35: 43964 | E35: =IF(D35="","", IF(ISNUMBER(D35),D35, IFERROR(DATEVALUE(D35), IFERROR(DATEVALUE(SUBSTITUTE(SUBSTITUTE(SUBSTITUTE(LOWER(D35),"th",""),".","/"),"-","/")),"Check")))) -> 43964 | F35: Analyst | G35: AI | H35: Intern | I35: PRJ-041 | J35: PRJ-081 | L35: =IF(E35="","Missing",YEAR(E35)) -> 2020 | M35: =IF(E35="","Missing","Q"&ROUNDUP(MONTH(E35)/3,0)) -> Q2 | N35: =YEAR(E35)&"-Q"&ROUNDUP(MONTH(E35)/3,0) -> 2020-Q2
A36: EMP035 | B36: ="emp"&TEXT(VALUE(SUBSTITUTE(SUBSTITUTE(UPPER(TRIM(A36)),"EMP",""),"-","")),"000") -> emp035 | C36: Abhishek Sen | D36: 44499 | E36: =IF(D36="","", IF(ISNUMBER(D36),D36, IFERROR(DATEVALUE(D36), IFERROR(DATEVALUE(SUBSTITUTE(SUBSTITUTE(SUBSTITUTE(LOWER(D36),"th",""),".","/"),"-","/")),"Check")))) -> 44499 | F36: Consultant | G36: Digital | H36: FTE | I36: PRJ-034 | J36: PRJ-089 | L36: =IF(E36="","Missing",YEAR(E36)) -> 2021 | M36: =IF(E36="","Missing","Q"&ROUNDUP(MONTH(E36)/3,0)) -> Q4 | N36: =YEAR(E36)&"-Q"&ROUNDUP(MONTH(E36)/3,0) -> 2021-Q4
A37: emp036 | B37: ="emp"&TEXT(VALUE(SUBSTITUTE(SUBSTITUTE(UPPER(TRIM(A37)),"EMP",""),"-","")),"000") -> emp036 | C37: Meenal Kulkarni | D37: 43147 | E37: =IF(D37="","", IF(ISNUMBER(D37),D37, IFERROR(DATEVALUE(D37), IFERROR(DATEVALUE(SUBSTITUTE(SUBSTITUTE(SUBSTITUTE(LOWER(D37),"th",""),".","/"),"-","/")),"Check")))) -> 43147 | F37: Lead Consultant | G37: Data | H37: FTE | I37: PRJ-030 | J37: PRJ-071 | K37: PRJ-079 | L37: =IF(E37="","Missing",YEAR(E37)) -> 2018 | M37: =IF(E37="","Missing","Q"&ROUNDUP(MONTH(E37)/3,0)) -> Q1 | N37: =YEAR(E37)&"-Q"&ROUNDUP(MONTH(E37)/3,0) -> 2018-Q1
A38: EMP-037 | B38: ="emp"&TEXT(VALUE(SUBSTITUTE(SUBSTITUTE(UPPER(TRIM(A38)),"EMP",""),"-","")),"000") -> emp037 | C38: Rohan Iyer | D38: 43717 | E38: =IF(D38="","", IF(ISNUMBER(D38),D38, IFERROR(DATEVALUE(D38), IFERROR(DATEVALUE(SUBSTITUTE(SUBSTITUTE(SUBSTITUTE(LOWER(D38),"th",""),".","/"),"-","/")),"Check")))) -> 43717 | F38: Consultant | G38: AI | H38: FTE | I38: PRJ-002 | J38: PRJ-056 | L38: =IF(E38="","Missing",YEAR(E38)) -> 2019 | M38: =IF(E38="","Missing","Q"&ROUNDUP(MONTH(E38)/3,0)) -> Q3 | N38: =YEAR(E38)&"-Q"&ROUNDUP(MONTH(E38)/3,0) -> 2019-Q3
A39: EMP038 | B39: ="emp"&TEXT(VALUE(SUBSTITUTE(SUBSTITUTE(UPPER(TRIM(A39)),"EMP",""),"-","")),"000") -> emp038 | C39: Simran Kaur | D39: 44585 | E39: =IF(D39="","", IF(ISNUMBER(D39),D39, IFERROR(DATEVALUE(D39), IFERROR(DATEVALUE(SUBSTITUTE(SUBSTITUTE(SUBSTITUTE(LOWER(D39),"th",""),".","/"),"-","/")),"Check")))) -> 44585 | F39: Analyst | G39: Digital | H39: Intern | I39: PRJ-040 | L39: =IF(E39="","Missing",YEAR(E39)) -> 2022 | M39: =IF(E39="","Missing","Q"&ROUNDUP(MONTH(E39)/3,0)) -> Q1 | N39: =YEAR(E39)&"-Q"&ROUNDUP(MONTH(E39)/3,0) -> 2022-Q1
A40: EMP-039 | B40: ="emp"&TEXT(VALUE(SUBSTITUTE(SUBSTITUTE(UPPER(TRIM(A40)),"EMP",""),"-","")),"000") -> emp039 | C40: Gaurav Bhatia | D40: 42311 | E40: =IF(D40="","", IF(ISNUMBER(D40),D40, IFERROR(DATEVALUE(D40), IFERROR(DATEVALUE(SUBSTITUTE(SUBSTITUTE(SUBSTITUTE(LOWER(D40),"th",""),".","/"),"-","/")),"Check")))) -> 42311 | F40: Senior Consultant | G40: Data | H40: Freelancer | I40: PRJ-002 | J40: PRJ-088 | L40: =IF(E40="","Missing",YEAR(E40)) -> 2015 | M40: =IF(E40="","Missing","Q"&ROUNDUP(MONTH(E40)/3,0)) -> Q4 | N40: =YEAR(E40)&"-Q"&ROUNDUP(MONTH(E40)/3,0) -> 2015-Q4
...

Sheet Projects
A1: Project ID | B1: Project Name | C1: Start Date | D1: Corrected Start Date | E1: End Date | F1: Corrected End Date | G1: Revised End Date | H1: Final End Date | I1: Duration (>3 months running projects in green) | J1: Project Type Duration Wise | K1: Project Status | L1: Delay
A2: PRJ-001 | B2: Digital Revamp | C2: 45880 | D2: =IF(C2="","", IF(ISNUMBER(C2),C2, IFERROR(DATEVALUE(C2), IFERROR(DATEVALUE(SUBSTITUTE(SUBSTITUTE(C2,"-","/"),",","")),"Check")))) -> 45880 | E2: 46038 | F2: =IF(E2="","", IF(ISNUMBER(E2),E2, IFERROR(DATEVALUE(E2), IFERROR(DATEVALUE(SUBSTITUTE(SUBSTITUTE(E2,"-","/"),",","")),"Check")))) -> 46038 | G2: 46322 | H2: =IF(G2<>"",G2,F2) -> 46322 | I2: =IF(OR(NOT(ISNUMBER(C2)),NOT(ISNUMBER(H2))),"",H2-C2) -> 442 | J2: =IF(I2>90,"Long Project","Normal") -> Long Project | K2: =IF(OR(H2="",NOT(ISNUMBER(H2))), "Planned/In Progress", IF(H2<TODAY(),"Completed","In Progress")) -> In Progress | L2: =IF(OR(NOT(ISNUMBER(F2)),NOT(ISNUMBER(H2))), "Missing", IF(H2<TODAY(), IF(H2>F2,H2-F2,"On Time"), "In Progress")) -> In Progress
A3: PRJ-002 | B3: AI Chatbot Rollout | C3: 45901 | D3: =IF(C3="","", IF(ISNUMBER(C3),C3, IFERROR(DATEVALUE(C3), IFERROR(DATEVALUE(SUBSTITUTE(SUBSTITUTE(C3,"-","/"),",","")),"Check")))) -> 45901 | E3: 46298 | F3: =IF(E3="","", IF(ISNUMBER(E3),E3, IFERROR(DATEVALUE(E3), IFERROR(DATEVALUE(SUBSTITUTE(SUBSTITUTE(E3,"-","/"),",","")),"Check")))) -> 46298 | H3: =IF(G3<>"",G3,F3) -> 46298 | I3: =IF(OR(NOT(ISNUMBER(C3)),NOT(ISNUMBER(H3))),"",H3-C3) -> 397 | J3: =IF(I3>90,"Long Project","Normal") -> Long Project | K3: =IF(OR(H3="",NOT(ISNUMBER(H3))), "Planned/In Progress", IF(H3<TODAY(),"Completed","In Progress")) -> In Progress | L3: =IF(OR(NOT(ISNUMBER(F3)),NOT(ISNUMBER(H3))), "Missing", IF(H3<TODAY(), IF(H3>F3,H3-F3,"On Time"), "In Progress")) -> In Progress
A4: PRJ-003 | B4: Cloud Migration Phase 1 | C4: 45915 | D4: =IF(C4="","", IF(ISNUMBER(C4),C4, IFERROR(DATEVALUE(C4), IFERROR(DATEVALUE(SUBSTITUTE(SUBSTITUTE(C4,"-","/"),",","")),"Check")))) -> 45915 | E4: 46022 | F4: =IF(E4="","", IF(ISNUMBER(E4),E4, IFERROR(DATEVALUE(E4), IFERROR(DATEVALUE(SUBSTITUTE(SUBSTITUTE(E4,"-","/"),",","")),"Check")))) -> 46022 | G4: 46108 | H4: =IF(G4<>"",G4,F4) -> 46108 | I4: =IF(OR(NOT(ISNUMBER(C4)),NOT(ISNUMBER(H4))),"",H4-C4) -> 193 | J4: =IF(I4>90,"Long Project","Normal") -> Long Project | K4: =IF(OR(H4="",NOT(ISNUMBER(H4))), "Planned/In Progress", IF(H4<TODAY(),"Completed","In Progress")) -> Completed | L4: =IF(OR(NOT(ISNUMBER(F4)),NOT(ISNUMBER(H4))), "Missing", IF(H4<TODAY(), IF(H4>F4,H4-F4,"On Time"), "In Progress")) -> 86
A5: PRJ-004 | B5: Data Lake Setup | C5: 46069 | D5: =IF(C5="","", IF(ISNUMBER(C5),C5, IFERROR(DATEVALUE(C5), IFERROR(DATEVALUE(SUBSTITUTE(SUBSTITUTE(C5,"-","/"),",","")),"Check")))) -> 46069 | E5: 46136 | F5: =IF(E5="","", IF(ISNUMBER(E5),E5, IFERROR(DATEVALUE(E5), IFERROR(DATEVALUE(SUBSTITUTE(SUBSTITUTE(E5,"-","/"),",","")),"Check")))) -> 46136 | H5: =IF(G5<>"",G5,F5) -> 46136 | I5: =IF(OR(NOT(ISNUMBER(C5)),NOT(ISNUMBER(H5))),"",H5-C5) -> 67 | J5: =IF(I5>90,"Long Project","Normal") -> Normal | K5: =IF(OR(H5="",NOT(ISNUMBER(H5))), "Planned/In Progress", IF(H5<TODAY(),"Completed","In Progress")) -> In Progress | L5: =IF(OR(NOT(ISNUMBER(F5)),NOT(ISNUMBER(H5))), "Missing", IF(H5<TODAY(), IF(H5>F5,H5-F5,"On Time"), "In Progress")) -> In Progress
A6: PRJ-005 | B6: CRM Enhancement | C6: 45510 | D6: =IF(C6="","", IF(ISNUMBER(C6),C6, IFERROR(DATEVALUE(C6), IFERROR(DATEVALUE(SUBSTITUTE(SUBSTITUTE(C6,"-","/"),",","")),"Check")))) -> 45510 | E6: 46127 | F6: =IF(E6="","", IF(ISNUMBER(E6),E6, IFERROR(DATEVALUE(E6), IFERROR(DATEVALUE(SUBSTITUTE(SUBSTITUTE(E6,"-","/"),",","")),"Check")))) -> 46127 | H6: =IF(G6<>"",G6,F6) -> 46127 | I6: =IF(OR(NOT(ISNUMBER(C6)),NOT(ISNUMBER(H6))),"",H6-C6) -> 617 | J6: =IF(I6>90,"Long Project","Normal") -> Long Project | K6: =IF(OR(H6="",NOT(ISNUMBER(H6))), "Planned/In Progress", IF(H6<TODAY(),"Completed","In Progress")) -> In Progress | L6: =IF(OR(NOT(ISNUMBER(F6)),NOT(ISNUMBER(H6))), "Missing", IF(H6<TODAY(), IF(H6>F6,H6-F6,"On Time"), "In Progress")) -> In Progress
A7: PRJ-006 | B7: Mobile App Redesign | C7: 45748 | D7: =IF(C7="","", IF(ISNUMBER(C7),C7, IFERROR(DATEVALUE(C7), IFERROR(DATEVALUE(SUBSTITUTE(SUBSTITUTE(C7,"-","/"),",","")),"Check")))) -> 45748 | E7: 46387 | F7: =IF(E7="","", IF(ISNUMBER(E7),E7, IFERROR(DATEVALUE(E7), IFERROR(DATEVALUE(SUBSTITUTE(SUBSTITUTE(E7,"-","/"),",","")),"Check")))) -> 46387 | H7: =IF(G7<>"",G7,F7) -> 46387 | I7: =IF(OR(NOT(ISNUMBER(C7)),NOT(ISNUMBER(H7))),"",H7-C7) -> 639 | J7: =IF(I7>90,"Long Project","Normal") -> Long Project | K7: =IF(OR(H7="",NOT(ISNUMBER(H7))), "Planned/In Progress", IF(H7<TODAY(),"Completed","In Progress")) -> In Progress | L7: =IF(OR(NOT(ISNUMBER(F7)),NOT(ISNUMBER(H7))), "Missing", IF(H7<TODAY(), IF(H7>F7,H7-F7,"On Time"), "In Progress")) -> In Progress
A8: PRJ-007 | B8: AI Demand Forecasting | C8: 45458 | D8: =IF(C8="","", IF(ISNUMBER(C8),C8, IFERROR(DATEVALUE(C8), IFERROR(DATEVALUE(SUBSTITUTE(SUBSTITUTE(C8,"-","/"),",","")),"Check")))) -> 45458 | E8: 46265 | F8: =IF(E8="","", IF(ISNUMBER(E8),E8, IFERROR(DATEVALUE(E8), IFERROR(DATEVALUE(SUBSTITUTE(SUBSTITUTE(E8,"-","/"),",","")),"Check")))) -> 46265 | H8: =IF(G8<>"",G8,F8) -> 46265 | I8: =IF(OR(NOT(ISNUMBER(C8)),NOT(ISNUMBER(H8))),"",H8-C8) -> 807 | J8: =IF(I8>90,"Long Project","Normal") -> Long Project | K8: =IF(OR(H8="",NOT(ISNUMBER(H8))), "Planned/In Progress", IF(H8<TODAY(),"Completed","In Progress")) -> In Progress | L8: =IF(OR(NOT(ISNUMBER(F8)),NOT(ISNUMBER(H8))), "Missing", IF(H8<TODAY(), IF(H8>F8,H8-F8,"On Time"), "In Progress")) -> In Progress
A9: PRJ-008 | B9: QA Automation Suite | C9: 45425 | D9: =IF(C9="","", IF(ISNUMBER(C9),C9, IFERROR(DATEVALUE(C9), IFERROR(DATEVALUE(SUBSTITUTE(SUBSTITUTE(C9,"-","/"),",","")),"Check")))) -> 45425 | E9: 46188 | F9: =IF(E9="","", IF(ISNUMBER(E9),E9, IFERROR(DATEVALUE(E9), IFERROR(DATEVALUE(SUBSTITUTE(SUBSTITUTE(E9,"-","/"),",","")),"Check")))) -> 46188 | H9: =IF(G9<>"",G9,F9) -> 46188 | I9: =IF(OR(NOT(ISNUMBER(C9)),NOT(ISNUMBER(H9))),"",H9-C9) -> 763 | J9: =IF(I9>90,"Long Project","Normal") -> Long Project | K9: =IF(OR(H9="",NOT(ISNUMBER(H9))), "Planned/In Progress", IF(H9<TODAY(),"Completed","In Progress")) -> In Progress | L9: =IF(OR(NOT(ISNUMBER(F9)),NOT(ISNUMBER(H9))), "Missing", IF(H9<TODAY(), IF(H9>F9,H9-F9,"On Time"), "In Progress")) -> In Progress
A10: PRJ-009 | B10: Cloud Cost Optimization | C10: 45689 | D10: =IF(C10="","", IF(ISNUMBER(C10),C10, IFERROR(DATEVALUE(C10), IFERROR(DATEVALUE(SUBSTITUTE(SUBSTITUTE(C10,"-","/"),",","")),"Check")))) -> 45689 | E10: 46142 | F10: =IF(E10="","", IF(ISNUMBER(E10),E10, IFERROR(DATEVALUE(E10), IFERROR(DATEVALUE(SUBSTITUTE(SUBSTITUTE(E10,"-","/"),",","")),"Check")))) -> 46142 | H10: =IF(G10<>"",G10,F10) -> 46142 | I10: =IF(OR(NOT(ISNUMBER(C10)),NOT(ISNUMBER(H10))),"",H10-C10) -> 453 | J10: =IF(I10>90,"Long Project","Normal") -> Long Project | K10: =IF(OR(H10="",NOT(ISNUMBER(H10))), "Planned/In Progress", IF(H10<TODAY(),"Completed","In Progress")) -> In Progress | L10: =IF(OR(NOT(ISNUMBER(F10)),NOT(ISNUMBER(H10))), "Missing", IF(H10<TODAY(), IF(H10>F10,H10-F10,"On Time"), "In Progress")) -> In Progress
A11: PRJ-010 | B11: Website Performance Boost | C11: 45847 | D11: =IF(C11="","", IF(ISNUMBER(C11),C11, IFERROR(DATEVALUE(C11), IFERROR(DATEVALUE(SUBSTITUTE(SUBSTITUTE(C11,"-","/"),",","")),"Check")))) -> 45847 | E11: 46249 | F11: =IF(E11="","", IF(ISNUMBER(E11),E11, IFERROR(DATEVALUE(E11), IFERROR(DATEVALUE(SUBSTITUTE(SUBSTITUTE(E11,"-","/"),",","")),"Check")))) -> 46249 | H11: =IF(G11<>"",G11,F11) -> 46249 | I11: =IF(OR(NOT(ISNUMBER(C11)),NOT(ISNUMBER(H11))),"",H11-C11) -> 402 | J11: =IF(I11>90,"Long Project","Normal") -> Long Project | K11: =IF(OR(H11="",NOT(ISNUMBER(H11))), "Planned/In Progress", IF(H11<TODAY(),"Completed","In Progress")) -> In Progress | L11: =IF(OR(NOT(ISNUMBER(F11)),NOT(ISNUMBER(H11))), "Missing", IF(H11<TODAY(), IF(H11>F11,H11-F11,"On Time"), "In Progress")) -> In Progress
A12: PRJ-011 | B12: AI Resume Screener | C12: 45764 | D12: =IF(C12="","", IF(ISNUMBER(C12),C12, IFERROR(DATEVALUE(C12), IFERROR(DATEVALUE(SUBSTITUTE(SUBSTITUTE(C12,"-","/"),",","")),"Check")))) -> 45764 | E12: 46128 | F12: =IF(E12="","", IF(ISNUMBER(E12),E12, IFERROR(DATEVALUE(E12), IFERROR(DATEVALUE(SUBSTITUTE(SUBSTITUTE(E12,"-","/"),",","")),"Check")))) -> 46128 | H12: =IF(G12<>"",G12,F12) -> 46128 | I12: =IF(OR(NOT(ISNUMBER(C12)),NOT(ISNUMBER(H12))),"",H12-C12) -> 364 | J12: =IF(I12>90,"Long Project","Normal") -> Long Project | K12: =IF(OR(H12="",NOT(ISNUMBER(H12))), "Planned/In Progress", IF(H12<TODAY(),"Completed","In Progress")) -> In Progress | L12: =IF(OR(NOT(ISNUMBER(F12)),NOT(ISNUMBER(H12))), "Missing", IF(H12<TODAY(), IF(H12>F12,H12-F12,"On Time"), "In Progress")) -> In Progress
A13: PRJ-012 | B13: Data Quality Program | C13: 45887 | D13: =IF(C13="","", IF(ISNUMBER(C13),C13, IFERROR(DATEVALUE(C13), IFERROR(DATEVALUE(SUBSTITUTE(SUBSTITUTE(C13,"-","/"),",","")),"Check")))) -> 45887 | E13: 46251 | F13: =IF(E13="","", IF(ISNUMBER(E13),E13, IFERROR(DATEVALUE(E13), IFERROR(DATEVALUE(SUBSTITUTE(SUBSTITUTE(E13,"-","/"),",","")),"Check")))) -> 46251 | H13: =IF(G13<>"",G13,F13) -> 46251 | I13: =IF(OR(NOT(ISNUMBER(C13)),NOT(ISNUMBER(H13))),"",H13-C13) -> 364 | J13: =IF(I13>90,"Long Project","Normal") -> Long Project | K13: =IF(OR(H13="",NOT(ISNUMBER(H13))), "Planned/In Progress", IF(H13<TODAY(),"Completed","In Progress")) -> In Progress | L13: =IF(OR(NOT(ISNUMBER(F13)),NOT(ISNUMBER(H13))), "Missing", IF(H13<TODAY(), IF(H13>F13,H13-F13,"On Time"), "In Progress")) -> In Progress
A14: PRJ-013 | B14: PMO Dashboard Revamp | C14: 45880 | D14: =IF(C14="","", IF(ISNUMBER(C14),C14, IFERROR(DATEVALUE(C14), IFERROR(DATEVALUE(SUBSTITUTE(SUBSTITUTE(C14,"-","/"),",","")),"Check")))) -> 45880 | E14: 46290 | F14: =IF(E14="","", IF(ISNUMBER(E14),E14, IFERROR(DATEVALUE(E14), IFERROR(DATEVALUE(SUBSTITUTE(SUBSTITUTE(E14,"-","/"),",","")),"Check")))) -> 46290 | H14: =IF(G14<>"",G14,F14) -> 46290 | I14: =IF(OR(NOT(ISNUMBER(C14)),NOT(ISNUMBER(H14))),"",H14-C14) -> 410 | J14: =IF(I14>90,"Long Project","Normal") -> Long Project | K14: =IF(OR(H14="",NOT(ISNUMBER(H14))), "Planned/In Progress", IF(H14<TODAY(),"Completed","In Progress")) -> In Progress | L14: =IF(OR(NOT(ISNUMBER(F14)),NOT(ISNUMBER(H14))), "Missing", IF(H14<TODAY(), IF(H14>F14,H14-F14,"On Time"), "In Progress")) -> In Progress
A15: PRJ-014 | B15: Support Ticket Analytics | C15: 45887 | D15: =IF(C15="","", IF(ISNUMBER(C15),C15, IFERROR(DATEVALUE(C15), IFERROR(DATEVALUE(SUBSTITUTE(SUBSTITUTE(C15,"-","/"),",","")),"Check")))) -> 45887 | E15: 46332 | F15: =IF(E15="","", IF(ISNUMBER(E15),E15, IFERROR(DATEVALUE(E15), IFERROR(DATEVALUE(SUBSTITUTE(SUBSTITUTE(E15,"-","/"),",","")),"Check")))) -> 46332 | H15: =IF(G15<>"",G15,F15) -> 46332 | I15: =IF(OR(NOT(ISNUMBER(C15)),NOT(ISNUMBER(H15))),"",H15-C15) -> 445 | J15: =IF(I15>90,"Long Project","Normal") -> Long Project | K15: =IF(OR(H15="",NOT(ISNUMBER(H15))), "Planned/In Progress", IF(H15<TODAY(),"Completed","In Progress")) -> In Progress | L15: =IF(OR(NOT(ISNUMBER(F15)),NOT(ISNUMBER(H15))), "Missing", IF(H15<TODAY(), IF(H15>F15,H15-F15,"On Time"), "In Progress")) -> In Progress
A16: PRJ-015 | B16: Digital Marketing Platform | C16: 45887 | D16: =IF(C16="","", IF(ISNUMBER(C16),C16, IFERROR(DATEVALUE(C16), IFERROR(DATEVALUE(SUBSTITUTE(SUBSTITUTE(C16,"-","/"),",","")),"Check")))) -> 45887 | E16: 46297 | F16: =IF(E16="","", IF(ISNUMBER(E16),E16, IFERROR(DATEVALUE(E16), IFERROR(DATEVALUE(SUBSTITUTE(SUBSTITUTE(E16,"-","/"),",","")),"Check")))) -> 46297 | H16: =IF(G16<>"",G16,F16) -> 46297 | I16: =IF(OR(NOT(ISNUMBER(C16)),NOT(ISNUMBER(H16))),"",H16-C16) -> 410 | J16: =IF(I16>90,"Long Project","Normal") -> Long Project | K16: =IF(OR(H16="",NOT(ISNUMBER(H16))), "Planned/In Progress", IF(H16<TODAY(),"Completed","In Progress")) -> In Progress | L16: =IF(OR(NOT(ISNUMBER(F16)),NOT(ISNUMBER(H16))), "Missing", IF(H16<TODAY(), IF(H16>F16,H16-F16,"On Time"), "In Progress")) -> In Progress
... A24: PRJ-023 | B24: Digital Sales Dashboard | C24: 45887 | D24: =IF(C24="","", IF(ISNUMBER(C24),C24, IFERROR(DATEVALUE(C24), IFERROR(DATEVALUE(SUBSTITUTE(SUBSTITUTE(C24,"-","/"),",","")),"Check")))) -> 45887 | E24: 46297 | F24: =IF(E24="","", IF(ISNUMBER(E24),E24, IFERROR(DATEVALUE(E24), IFERROR(DATEVALUE(SUBSTITUTE(SUBSTITUTE(E24,"-","/"),",","")),"Check")))) -> 46297 | H24: =IF(G24<>"",G24,F24) -> 46297 | I24: =IF(OR(NOT(ISNUMBER(C24)),NOT(ISNUMBER(H24))),"",H24-C24) -> 410 | J24: =IF(I24>90,"Long Project","Normal") -> Long Project | K24: =IF(OR(H24="",NOT(ISNUMBER(H24))), "Planned/In Progress", IF(H24<TODAY(),"Completed","In Progress")) -> In Progress | L24: =IF(OR(NOT(ISNUMBER(F24)),NOT(ISNUMBER(H24))), "Missing", IF(H24<TODAY(), IF(H24>F24,H24-F24,"On Time"), "In Progress")) -> In Progress
A25: PRJ-024 | B25: Support Knowledge Base | C25: 45160 | D25: =IF(C25="","", IF(ISNUMBER(C25),C25, IFERROR(DATEVALUE(C25), IFERROR(DATEVALUE(SUBSTITUTE(SUBSTITUTE(C25,"-","/"),",","")),"Check")))) -> 45160 | E25: 45991 | F25: =IF(E25="","", IF(ISNUMBER(E25),E25, IFERROR(DATEVALUE(E25), IFERROR(DATEVALUE(SUBSTITUTE(SUBSTITUTE(E25,"-","/"),",","")),"Check")))) -> 45991 | G25: 46058 | H25: =IF(G25<>"",G25,F25) -> 46058 | I25: =IF(OR(NOT(ISNUMBER(C25)),NOT(ISNUMBER(H25))),"",H25-C25) -> 898 | J25: =IF(I25>90,"Long Project","Normal") -> Long Project | K25: =IF(OR(H25="",NOT(ISNUMBER(H25))), "Planned/In Progress", IF(H25<TODAY(),"Completed","In Progress")) -> Completed | L25: =IF(OR(NOT(ISNUMBER(F25)),NOT(ISNUMBER(H25))), "Missing", IF(H25<TODAY(), IF(H25>F25,H25-F25,"On Time"), "In Progress")) -> 67
A26: PRJ-025 | B26: AI Voice Bot | C26: 45908 | D26: =IF(C26="","", IF(ISNUMBER(C26),C26, IFERROR(DATEVALUE(C26), IFERROR(DATEVALUE(SUBSTITUTE(SUBSTITUTE(C26,"-","/"),",","")),"Check")))) -> 45908 | E26: 46387 | F26: =IF(E26="","", IF(ISNUMBER(E26),E26, IFERROR(DATEVALUE(E26), IFERROR(DATEVALUE(SUBSTITUTE(SUBSTITUTE(E26,"-","/"),",","")),"Check")))) -> 46387 | H26: =IF(G26<>"",G26,F26) -> 46387 | I26: =IF(OR(NOT(ISNUMBER(C26)),NOT(ISNUMBER(H26))),"",H26-C26) -> 479 | J26: =IF(I26>90,"Long Project","Normal") -> Long Project | K26: =IF(OR(H26="",NOT(ISNUMBER(H26))), "Planned/In Progress", IF(H26<TODAY(),"Completed","In Progress")) -> In Progress | L26: =IF(OR(NOT(ISNUMBER(F26)),NOT(ISNUMBER(H26))), "Missing", IF(H26<TODAY(), IF(H26>F26,H26-F26,"On Time"), "In Progress")) -> In Progress
A27: PRJ-026 | B27: Data Governance Setup | C27: 45922 | D27: =IF(C27="","", IF(ISNUMBER(C27),C27, IFERROR(DATEVALUE(C27), IFERROR(DATEVALUE(SUBSTITUTE(SUBSTITUTE(C27,"-","/"),",","")),"Check")))) -> 45922 | E27: 45996 | F27: =IF(E27="","", IF(ISNUMBER(E27),E27, IFERROR(DATEVALUE(E27), IFERROR(DATEVALUE(SUBSTITUTE(SUBSTITUTE(E27,"-","/"),",","")),"Check")))) -> 45996 | G27: 46234 | H27: =IF(G27<>"",G27,F27) -> 46234 | I27: =IF(OR(NOT(ISNUMBER(C27)),NOT(ISNUMBER(H27))),"",H27-C27) -> 312 | J27: =IF(I27>90,"Long Project","Normal") -> Long Project | K27: =IF(OR(H27="",NOT(ISNUMBER(H27))), "Planned/In Progress", IF(H27<TODAY(),"Completed","In Progress")) -> In Progress | L27: =IF(OR(NOT(ISNUMBER(F27)),NOT(ISNUMBER(H27))), "Missing", IF(H27<TODAY(), IF(H27>F27,H27-F27,"On Time"), "In Progress")) -> In Progress
A28: PRJ-027 | B28: Cloud App Modernization | C28: 45981 | D28: =IF(C28="","", IF(ISNUMBER(C28),C28, IFERROR(DATEVALUE(C28), IFERROR(DATEVALUE(SUBSTITUTE(SUBSTITUTE(C28,"-","/"),",","")),"Check")))) -> 45981 | E28: 46203 | F28: =IF(E28="","", IF(ISNUMBER(E28),E28, IFERROR(DATEVALUE(E28), IFERROR(DATEVALUE(SUBSTITUTE(SUBSTITUTE(E28,"-","/"),",","")),"Check")))) -> 46203 | H28: =IF(G28<>"",G28,F28) -> 46203 | I28: =IF(OR(NOT(ISNUMBER(C28)),NOT(ISNUMBER(H28))),"",H28-C28) -> 222 | J28: =IF(I28>90,"Long Project","Normal") -> Long Project | K28: =IF(OR(H28="",NOT(ISNUMBER(H28))), "Planned/In Progress", IF(H28<TODAY(),"Completed","In Progress")) -> In Progress | L28: =IF(OR(NOT(ISNUMBER(F28)),NOT(ISNUMBER(H28))), "Missing", IF(H28<TODAY(), IF(H28>F28,H28-F28,"On Time"), "In Progress")) -> In Progress
A29: PRJ-028 | B29: QA Metrics Dashboard | C29: 45931 | D29: =IF(C29="","", IF(ISNUMBER(C29),C29, IFERROR(DATEVALUE(C29), IFERROR(DATEVALUE(SUBSTITUTE(SUBSTITUTE(C29,"-","/"),",","")),"Check")))) -> 45931 | E29: 46023 | F29: =IF(E29="","", IF(ISNUMBER(E29),E29, IFERROR(DATEVALUE(E29), IFERROR(DATEVALUE(SUBSTITUTE(SUBSTITUTE(E29,"-","/"),",","")),"Check")))) -> 46023 | G29: 46080 | H29: =IF(G29<>"",G29,F29) -> 46080 | I29: =IF(OR(NOT(ISNUMBER(C29)),NOT(ISNUMBER(H29))),"",H29-C29) -> 149 | J29: =IF(I29>90,"Long Project","Normal") -> Long Project | K29: =IF(OR(H29="",NOT(ISNUMBER(H29))), "Planned/In Progress", IF(H29<TODAY(),"Completed","In Progress")) -> Completed | L29: =IF(OR(NOT(ISNUMBER(F29)),NOT(ISNUMBER(H29))), "Missing", IF(H29<TODAY(), IF(H29>F29,H29-F29,"On Time"), "In Progress")) -> 57
A30: PRJ-029 | B30: Digital Onboarding Flow | C30: 46030 | D30: =IF(C30="","", IF(ISNUMBER(C30),C30, IFERROR(DATEVALUE(C30), IFERROR(DATEVALUE(SUBSTITUTE(SUBSTITUTE(C30,"-","/"),",","")),"Check")))) -> 46030 | E30: 46115 | F30: =IF(E30="","", IF(ISNUMBER(E30),E30, IFERROR(DATEVALUE(E30), IFERROR(DATEVALUE(SUBSTITUTE(SUBSTITUTE(E30,"-","/"),",","")),"Check")))) -> 46115 | G30: 46136 | H30: =IF(G30<>"",G30,F30) -> 46136 | I30: =IF(OR(NOT(ISNUMBER(C30)),NOT(ISNUMBER(H30))),"",H30-C30) -> 106 | J30: =IF(I30>90,"Long Project","Normal") -> Long Project | K30: =IF(OR(H30="",NOT(ISNUMBER(H30))), "Planned/In Progress", IF(H30<TODAY(),"Completed","In Progress")) -> In Progress | L30: =IF(OR(NOT(ISNUMBER(F30)),NOT(ISNUMBER(H30))), "Missing", IF(H30<TODAY(), IF(H30>F30,H30-F30,"On Time"), "In Progress")) -> In Progress
A31: PRJ-030 | B31: AI Chat Analytics | C31: 45908 | D31: =IF(C31="","", IF(ISNUMBER(C31),C31, IFERROR(DATEVALUE(C31), IFERROR(DATEVALUE(SUBSTITUTE(SUBSTITUTE(C31,"-","/"),",","")),"Check")))) -> 45908 | E31: 46022 | F31: =IF(E31="","", IF(ISNUMBER(E31),E31, IFERROR(DATEVALUE(E31), IFERROR(DATEVALUE(SUBSTITUTE(SUBSTITUTE(E31,"-","/"),",","")),"Check")))) -> 46022 | G31: 46066 | H31: =IF(G31<>"",G31,F31) -> 46066 | I31: =IF(OR(NOT(ISNUMBER(C31)),NOT(ISNUMBER(H31))),"",H31-C31) -> 158 | J31: =IF(I31>90,"Long Project","Normal") -> Long Project | K31: =IF(OR(H31="",NOT(ISNUMBER(H31))), "Planned/In Progress", IF(H31<TODAY(),"Completed","In Progress")) -> Completed | L31: =IF(OR(NOT(ISNUMBER(F31)),NOT(ISNUMBER(H31))), "Missing", IF(H31<TODAY(), IF(H31>F31,H31-F31,"On Time"), "In Progress")) -> 44
A32: PRJ-031 | B32: Support Automation | C32: 45748 | D32: =IF(C32="","", IF(ISNUMBER(C32),C32, IFERROR(DATEVALUE(C32), IFERROR(DATEVALUE(SUBSTITUTE(SUBSTITUTE(C32,"-","/"),",","")),"Check")))) -> 45748 | E32: 45838 | F32: =IF(E32="","", IF(ISNUMBER(E32),E32, IFERROR(DATEVALUE(E32), IFERROR(DATEVALUE(SUBSTITUTE(SUBSTITUTE(E32,"-","/"),",","")),"Check")))) -> 45838 | H32: =IF(G32<>"",G32,F32) -> 45838 | I32: =IF(OR(NOT(ISNUMBER(C32)),NOT(ISNUMBER(H32))),"",H32-C32) -> 90 | J32: =IF(I32>90,"Long Project","Normal") -> Normal | K32: =IF(OR(H32="",NOT(ISNUMBER(H32))), "Planned/In Progress", IF(H32<TODAY(),"Completed","In Progress")) -> Completed | L32: =IF(OR(NOT(ISNUMBER(F32)),NOT(ISNUMBER(H32))), "Missing", IF(H32<TODAY(), IF(H32>F32,H32-F32,"On Time"), "In Progress")) -> On Time
A33: PRJ-032 | B33: Cloud Monitoring Setup | C33: 45748 | D33: =IF(C33="","", IF(ISNUMBER(C33),C33, IFERROR(DATEVALUE(C33), IFERROR(DATEVALUE(SUBSTITUTE(SUBSTITUTE(C33,"-","/"),",","")),"Check")))) -> 45748 | E33: 46265 | F33: =IF(E33="","", IF(ISNUMBER(E33),E33, IFERROR(DATEVALUE(E33), IFERROR(DATEVALUE(SUBSTITUTE(SUBSTITUTE(E33,"-","/"),",","")),"Check")))) -> 46265 | H33: =IF(G33<>"",G33,F33) -> 46265 | I33: =IF(OR(NOT(ISNUMBER(C33)),NOT(ISNUMBER(H33))),"",H33-C33) -> 517 | J33: =IF(I33>90,"Long Project","Normal") -> Long Project | K33: =IF(OR(H33="",NOT(ISNUMBER(H33))), "Planned/In Progress", IF(H33<TODAY(),"Completed","In Progress")) -> In Progress | L33: =IF(OR(NOT(ISNUMBER(F33)),NOT(ISNUMBER(H33))), "Missing", IF(H33<TODAY(), IF(H33>F33,H33-F33,"On Time"), "In Progress")) -> In Progress
A34: PRJ-033 | B34: Data Reporting Factory | C34: 45748 | D34: =IF(C34="","", IF(ISNUMBER(C34),C34, IFERROR(DATEVALUE(C34), IFERROR(DATEVALUE(SUBSTITUTE(SUBSTITUTE(C34,"-","/"),",","")),"Check")))) -> 45748 | E34: 46276 | F34: =IF(E34="","", IF(ISNUMBER(E34),E34, IFERROR(DATEVALUE(E34), IFERROR(DATEVALUE(SUBSTITUTE(SUBSTITUTE(E34,"-","/"),",","")),"Check")))) -> 46276 | H34: =IF(G34<>"",G34,F34) -> 46276 | I34: =IF(OR(NOT(ISNUMBER(C34)),NOT(ISNUMBER(H34))),"",H34-C34) -> 528 | J34: =IF(I34>90,"Long Project","Normal") -> Long Project | K34: =IF(OR(H34="",NOT(ISNUMBER(H34))), "Planned/In Progress", IF(H34<TODAY(),"Completed","In Progress")) -> In Progress | L34: =IF(OR(NOT(ISNUMBER(F34)),NOT(ISNUMBER(H34))), "Missing", IF(H34<TODAY(), IF(H34>F34,H34-F34,"On Time"), "In Progress")) -> In Progress
A35: PRJ-034 | B35: Digital UX Cleanup | C35: 45748 | D35: =IF(C35="","", IF(ISNUMBER(C35),C35, IFERROR(DATEVALUE(C35), IFERROR(DATEVALUE(SUBSTITUTE(SUBSTITUTE(C35,"-","/"),",","")),"Check")))) -> 45748 | E35: 46112 | F35: =IF(E35="","", IF(ISNUMBER(E35),E35, IFERROR(DATEVALUE(E35), IFERROR(DATEVALUE(SUBSTITUTE(SUBSTITUTE(E35,"-","/"),",","")),"Check")))) -> 46112 | H35: =IF(G35<>"",G35,F35) -> 46112 | I35: =IF(OR(NOT(ISNUMBER(C35)),NOT(ISNUMBER(H35))),"",H35-C35) -> 364 | J35: =IF(I35>90,"Long Project","Normal") -> Long Project | K35: =IF(OR(H35="",NOT(ISNUMBER(H35))), "Planned/In Progress", IF(H35<TODAY(),"Completed","In Progress")) -> Completed | L35: =IF(OR(NOT(ISNUMBER(F35)),NOT(ISNUMBER(H35))), "Missing", IF(H35<TODAY(), IF(H35>F35,H35-F35,"On Time"), "In Progress")) -> On Time
A36: PRJ-035 | B36: QA Regression Automation | C36: 45748 | D36: =IF(C36="","", IF(ISNUMBER(C36),C36, IFERROR(DATEVALUE(C36), IFERROR(DATEVALUE(SUBSTITUTE(SUBSTITUTE(C36,"-","/"),",","")),"Check")))) -> 45748 | E36: 46170 | F36: =IF(E36="","", IF(ISNUMBER(E36),E36, IFERROR(DATEVALUE(E36), IFERROR(DATEVALUE(SUBSTITUTE(SUBSTITUTE(E36,"-","/"),",","")),"Check")))) -> 46170 | H36: =IF(G36<>"",G36,F36) -> 46170 | I36: =IF(OR(NOT(ISNUMBER(C36)),NOT(ISNUMBER(H36))),"",H36-C36) -> 422 | J36: =IF(I36>90,"Long Project","Normal") -> Long Project | K36: =IF(OR(H36="",NOT(ISNUMBER(H36))), "Planned/In Progress", IF(H36<TODAY(),"Completed","In Progress")) -> In Progress | L36: =IF(OR(NOT(ISNUMBER(F36)),NOT(ISNUMBER(H36))), "Missing", IF(H36<TODAY(), IF(H36>F36,H36-F36,"On Time"), "In Progress")) -> In Progress
A37: PRJ-036 | B37: AI Model Retraining | C37: 45748 | D37: =IF(C37="","", IF(ISNUMBER(C37),C37, IFERROR(DATEVALUE(C37), IFERROR(DATEVALUE(SUBSTITUTE(SUBSTITUTE(C37,"-","/"),",","")),"Check")))) -> 45748 | E37: 46324 | F37: =IF(E37="","", IF(ISNUMBER(E37),E37, IFERROR(DATEVALUE(E37), IFERROR(DATEVALUE(SUBSTITUTE(SUBSTITUTE(E37,"-","/"),",","")),"Check")))) -> 46324 | H37: =IF(G37<>"",G37,F37) -> 46324 | I37: =IF(OR(NOT(ISNUMBER(C37)),NOT(ISNUMBER(H37))),"",H37-C37) -> 576 | J37: =IF(I37>90,"Long Project","Normal") -> Long Project | K37: =IF(OR(H37="",NOT(ISNUMBER(H37))), "Planned/In Progress", IF(H37<TODAY(),"Completed","In Progress")) -> In Progress | L37: =IF(OR(NOT(ISNUMBER(F37)),NOT(ISNUMBER(H37))), "Missing", IF(H37<TODAY(), IF(H37>F37,H37-F37,"On Time"), "In Progress")) -> In Progress
A38: PRJ-037 | B38: Cloud Infra Audit | C38: 45748 | D38: =IF(C38="","", IF(ISNUMBER(C38),C38, IFERROR(DATEVALUE(C38), IFERROR(DATEVALUE(SUBSTITUTE(SUBSTITUTE(C38,"-","/"),",","")),"Check")))) -> 45748 | E38: 46387 | F38: =IF(E38="","", IF(ISNUMBER(E38),E38, IFERROR(DATEVALUE(E38), IFERROR(DATEVALUE(SUBSTITUTE(SUBSTITUTE(E38,"-","/"),",","")),"Check")))) -> 46387 | H38: =IF(G38<>"",G38,F38) -> 46387 | I38: =IF(OR(NOT(ISNUMBER(C38)),NOT(ISNUMBER(H38))),"",H38-C38) -> 639 | J38: =IF(I38>90,"Long Project","Normal") -> Long Project | K38: =IF(OR(H38="",NOT(ISNUMBER(H38))), "Planned/In Progress", IF(H38<TODAY(),"Completed","In Progress")) -> In Progress | L38: =IF(OR(NOT(ISNUMBER(F38)),NOT(ISNUMBER(H38))), "Missing", IF(H38<TODAY(), IF(H38>F38,H38-F38,"On Time"), "In Progress")) -> In Progress
A39: PRJ-038 | B39: Support SLA Tracker | C39: 45936 | D39: =IF(C39="","", IF(ISNUMBER(C39),C39, IFERROR(DATEVALUE(C39), IFERROR(DATEVALUE(SUBSTITUTE(SUBSTITUTE(C39,"-","/"),",","")),"Check")))) -> 45936 | E39: 46038 | F39: =IF(E39="","", IF(ISNUMBER(E39),E39, IFERROR(DATEVALUE(E39), IFERROR(DATEVALUE(SUBSTITUTE(SUBSTITUTE(E39,"-","/"),",","")),"Check")))) -> 46038 | H39: =IF(G39<>"",G39,F39) -> 46038 | I39: =IF(OR(NOT(ISNUMBER(C39)),NOT(ISNUMBER(H39))),"",H39-C39) -> 102 | J39: =IF(I39>90,"Long Project","Normal") -> Long Project | K39: =IF(OR(H39="",NOT(ISNUMBER(H39))), "Planned/In Progress", IF(H39<TODAY(),"Completed","In Progress")) -> Completed | L39: =IF(OR(NOT(ISNUMBER(F39)),NOT(ISNUMBER(H39))), "Missing", IF(H39<TODAY(), IF(H39>F39,H39-F39,"On Time"), "In Progress")) -> On Time
A40: PRJ-039 | B40: Data Cost Optimization | C40: 45929 | D40: =IF(C40="","", IF(ISNUMBER(C40),C40, IFERROR(DATEVALUE(C40), IFERROR(DATEVALUE(SUBSTITUTE(SUBSTITUTE(C40,"-","/"),",","")),"Check")))) -> 45929 | E40: 46310 | F40: =IF(E40="","", IF(ISNUMBER(E40),E40, IFERROR(DATEVALUE(E40), IFERROR(DATEVALUE(SUBSTITUTE(SUBSTITUTE(E40,"-","/"),",","")),"Check")))) -> 46310 | H40: =IF(G40<>"",G40,F40) -> 46310 | I40: =IF(OR(NOT(ISNUMBER(C40)),NOT(ISNUMBER(H40))),"",H40-C40) -> 381 | J40: =IF(I40>90,"Long Project","Normal") -> Long Project | K40: =IF(OR(H40="",NOT(ISNUMBER(H40))), "Planned/In Progress", IF(H40<TODAY(),"Completed","In Progress")) -> In Progress | L40: =IF(OR(NOT(ISNUMBER(F40)),NOT(ISNUMBER(H40))), "Missing", IF(H40<TODAY(), IF(H40>F40,H40-F40,"On Time"), "In Progress")) -> In Progress
A41: PRJ-040 | B41: Digital Campaign Tracker | C41: 45929 | D41: =IF(C41="","", IF(ISNUMBER(C41),C41, IFERROR(DATEVALUE(C41), IFERROR(DATEVALUE(SUBSTITUTE(SUBSTITUTE(C41,"-","/"),",","")),"Check")))) -> 45929 | E41: 46387 | F41: =IF(E41="","", IF(ISNUMBER(E41),E41, IFERROR(DATEVALUE(E41), IFERROR(DATEVALUE(SUBSTITUTE(SUBSTITUTE(E41,"-","/"),",","")),"Check")))) -> 46387 | H41: =IF(G41<>"",G41,F41) -> 46387 | I41: =IF(OR(NOT(ISNUMBER(C41)),NOT(ISNUMBER(H41))),"",H41-C41) -> 458 | J41: =IF(I41>90,"Long Project","Normal") -> Long Project | K41: =IF(OR(H41="",NOT(ISNUMBER(H41))), "Planned/In Progress", IF(H41<TODAY(),"Completed","In Progress")) -> In Progress | L41: =IF(OR(NOT(ISNUMBER(F41)),NOT(ISNUMBER(H41))), "Missing", IF(H41<TODAY(), IF(H41>F41,H41-F41,"On Time"), "In Progress")) -> In Progress
A42: PRJ-041 | B42: AI Knowledge Assistant | C42: 45929 | D42: =IF(C42="","", IF(ISNUMBER(C42),C42, IFERROR(DATEVALUE(C42), IFERROR(DATEVALUE(SUBSTITUTE(SUBSTITUTE(C42,"-","/"),",","")),"Check")))) -> 45929 | E42: 46387 | F42: =IF(E42="","", IF(ISNUMBER(E42),E42, IFERROR(DATEVALUE(E42), IFERROR(DATEVALUE(SUBSTITUTE(SUBSTITUTE(E42,"-","/"),",","")),"Check")))) -> 46387 | H42: =IF(G42<>"",G42,F42) -> 46387 | I42: =IF(OR(NOT(ISNUMBER(C42)),NOT(ISNUMBER(H42))),"",H42-C42) -> 458 | J42: =IF(I42>90,"Long Project","Normal") -> Long Project | K42: =IF(OR(H42="",NOT(ISNUMBER(H42))), "Planned/In Progress", IF(H42<TODAY(),"Completed","In Progress")) -> In Progress | L42: =IF(OR(NOT(ISNUMBER(F42)),NOT(ISNUMBER(H42))), "Missing", IF(H42<TODAY(), IF(H42>F42,H42-F42,"On Time"), "In Progress")) -> In Progress
A43: PRJ-042 | B43: QA Tool Evaluation | C43: 45915 | D43: =IF(C43="","", IF(ISNUMBER(C43),C43, IFERROR(DATEVALUE(C43), IFERROR(DATEVALUE(SUBSTITUTE(SUBSTITUTE(C43,"-","/"),",","")),"Check")))) -> 45915 | E43: 46081 | F43: =IF(E43="","", IF(ISNUMBER(E43),E43, IFERROR(DATEVALUE(E43), IFERROR(DATEVALUE(SUBSTITUTE(SUBSTITUTE(E43,"-","/"),",","")),"Check")))) -> 46081 | H43: =IF(G43<>"",G43,F43) -> 46081 | I43: =IF(OR(NOT(ISNUMBER(C43)),NOT(ISNUMBER(H43))),"",H43-C43) -> 166 | J43: =IF(I43>90,"Long Project","Normal") -> Long Project | K43: =IF(OR(H43="",NOT(ISNUMBER(H43))), "Planned/In Progress", IF(H43<TODAY(),"Completed","In Progress")) -> Completed | L43: =IF(OR(NOT(ISNUMBER(F43)),NOT(ISNUMBER(H43))), "Missing", IF(H43<TODAY(), IF(H43>F43,H43-F43,"On Time"), "In Progress")) -> On Time
... A47: PRJ-046 | B47: AI Testing Framework | C47: 46076 | D47: =IF(C47="","", IF(ISNUMBER(C47),C47, IFERROR(DATEVALUE(C47), IFERROR(DATEVALUE(SUBSTITUTE(SUBSTITUTE(C47,"-","/"),",","")),"Check")))) -> 46076 | E47: 46234 | F47: =IF(E47="","", IF(ISNUMBER(E47),E47, IFERROR(DATEVALUE(E47), IFERROR(DATEVALUE(SUBSTITUTE(SUBSTITUTE(E47,"-","/"),",","")),"Check")))) -> 46234 | H47: =IF(G47<>"",G47,F47) -> 46234 | I47: =IF(OR(NOT(ISNUMBER(C47)),NOT(ISNUMBER(H47))),"",H47-C47) -> 158 | J47: =IF(I47>90,"Long Project","Normal") -> Long Project | K47: =IF(OR(H47="",NOT(ISNUMBER(H47))), "Planned/In Progress", IF(H47<TODAY(),"Completed","In Progress")) -> In Progress | L47: =IF(OR(NOT(ISNUMBER(F47)),NOT(ISNUMBER(H47))), "Missing", IF(H47<TODAY(), IF(H47>F47,H47-F47,"On Time"), "In Progress")) -> In Progress
A48: PRJ-047 | B48: Support Load Analysis | C48: 45950 | D48: =IF(C48="","", IF(ISNUMBER(C48),C48, IFERROR(DATEVALUE(C48), IFERROR(DATEVALUE(SUBSTITUTE(SUBSTITUTE(C48,"-","/"),",","")),"Check")))) -> 45950 | E48: 46038 | F48: =IF(E48="","", IF(ISNUMBER(E48),E48, IFERROR(DATEVALUE(E48), IFERROR(DATEVALUE(SUBSTITUTE(SUBSTITUTE(E48,"-","/"),",","")),"Check")))) -> 46038 | G48: 46059 | H48: =IF(G48<>"",G48,F48) -> 46059 | I48: =IF(OR(NOT(ISNUMBER(C48)),NOT(ISNUMBER(H48))),"",H48-C48) -> 109 | J48: =IF(I48>90,"Long Project","Normal") -> Long Project | K48: =IF(OR(H48="",NOT(ISNUMBER(H48))), "Planned/In Progress", IF(H48<TODAY(),"Completed","In Progress")) -> Completed | L48: =IF(OR(NOT(ISNUMBER(F48)),NOT(ISNUMBER(H48))), "Missing", IF(H48<TODAY(), IF(H48>F48,H48-F48,"On Time"), "In Progress")) -> 21
A49: PRJ-048 | B49: Cloud Backup Automation | C49: 46023 | D49: =IF(C49="","", IF(ISNUMBER(C49),C49, IFERROR(DATEVALUE(C49), IFERROR(DATEVALUE(SUBSTITUTE(SUBSTITUTE(C49,"-","/"),",","")),"Check")))) -> 46023 | E49: 46171 | F49: =IF(E49="","", IF(ISNUMBER(E49),E49, IFERROR(DATEVALUE(E49), IFERROR(DATEVALUE(SUBSTITUTE(SUBSTITUTE(E49,"-","/"),",","")),"Check")))) -> 46171 | H49: =IF(G49<>"",G49,F49) -> 46171 | I49: =IF(OR(NOT(ISNUMBER(C49)),NOT(ISNUMBER(H49))),"",H49-C49) -> 148 | J49: =IF(I49>90,"Long Project","Normal") -> Long Project | K49: =IF(OR(H49="",NOT(ISNUMBER(H49))), "Planned/In Progress", IF(H49<TODAY(),"Completed","In Progress")) -> In Progress | L49: =IF(OR(NOT(ISNUMBER(F49)),NOT(ISNUMBER(H49))), "Missing", IF(H49<TODAY(), IF(H49>F49,H49-F49,"On Time"), "In Progress")) -> In Progress
A50: PRJ-049 | B50: Data Visualization Revamp | C50: 45912 | D50: =IF(C50="","", IF(ISNUMBER(C50),C50, IFERROR(DATEVALUE(C50), IFERROR(DATEVALUE(SUBSTITUTE(SUBSTITUTE(C50,"-","/"),",","")),"Check")))) -> 45912 | E50: 46326 | F50: =IF(E50="","", IF(ISNUMBER(E50),E50, IFERROR(DATEVALUE(E50), IFERROR(DATEVALUE(SUBSTITUTE(SUBSTITUTE(E50,"-","/"),",","")),"Check")))) -> 46326 | H50: =IF(G50<>"",G50,F50) -> 46326 | I50: =IF(OR(NOT(ISNUMBER(C50)),NOT(ISNUMBER(H50))),"",H50-C50) -> 414 | J50: =IF(I50>90,"Long Project","Normal") -> Long Project | K50: =IF(OR(H50="",NOT(ISNUMBER(H50))), "Planned/In Progress", IF(H50<TODAY(),"Completed","In Progress")) -> In Progress | L50: =IF(OR(NOT(ISNUMBER(F50)),NOT(ISNUMBER(H50))), "Missing", IF(H50<TODAY(), IF(H50>F50,H50-F50,"On Time"), "In Progress")) -> In Progress
...

Sheet Team Structure Analysis 
A3: Count of Employee Name | B3: Column Labels
A4: Row Labels | B4: FTE | C4: Intern | D4: Grand Total
A5: AI | B5: 11 | C5: 6 | D5: 17
A6: Analyst | B6: 1 | C6: 5 | D6: 6
A7: Consultant | B7: 5 | C7: 1 | D7: 6
A8: Lead Consultant | B8: 1 | D8: 1
A9: Principal Consultant | B9: 2 | D9: 2
A10: Sr. Consultant | B10: 2 | D10: 2
A11: Data | B11: 15 | C11: 6 | D11: 21
A12: Analyst | B12: 3 | C12: 6 | D12: 9
A13: Consultant | B13: 3 | D13: 3
A14: Lead Consultant | B14: 4 | D14: 4
A15: Senior Consultant | B15: 1 | D15: 1
A16: Sr Consultant | B16: 1 | D16: 1
A17: Sr. Consultant | B17: 3 | D17: 3
A18: Digital | B18: 12 | C18: 3 | D18: 15
A19: Analyst | C19: 3 | D19: 3
A20: Consultant | B20: 7 | D20: 7
A21: Lead Consultant | B21: 2 | D21: 2
A22: Manager | B22: 1 | D22: 1
A23: Senior Consultant | B23: 2 | D23: 2
A24: Grand Total | B24: 38 | C24: 15 | D24: 53
A27: I created a pivot-based interactive view using slicers to dynamically analyze employee distribution across teams, designations, and employment types.

Sheet Long-Running Projects Identific
A1: Project Type Duration Wise | B1: (All)
A3: Row Labels | B3: Count of Duration (>3 months running projects in green) | D3: I calculated project duration using cleaned start and end dates, incorporating revised timelines where available, and flagged projects exceeding 90 days.
A4: PRJ-001 | B4: 1
A5: PRJ-002 | B5: 1
A6: PRJ-003 | B6: 1
A7: PRJ-004 | B7: 1
A8: PRJ-005 | B8: 1
A9: PRJ-006 | B9: 1
A10: PRJ-007 | B10: 1
A11: PRJ-008 | B11: 1
A12: PRJ-009 | B12: 1
A13: PRJ-010 | B13: 1
A14: PRJ-011 | B14: 1
A15: PRJ-012 | B15: 1
... A94: Grand Total | B94: 90

Sheet Employee Cohort Filtering 
A3: Row Labels | B3: Count of Employee Name
A4: 2015 | B4: 2
A5: Q1 | B5: 1
A6: Q4 | B6: 1
A7: 2016 | B7: 15
A8: Q1 | B8: 3
A9: Q2 | B9: 6
A10: Q3 | B10: 2
A11: Q4 | B11: 4
A12: 2017 | B12: 16
A13: Q1 | B13: 6
A14: Q2 | B14: 5
A15: Q3 | B15: 3
A16: Q4 | B16: 2
A17: 2018 | B17: 14
A18: Q1 | B18: 4
A19: Q2 | B19: 3
A20: Q3 | B20: 3 | E20: I derived Year and Quarter from employee joining dates and built a pivot-based cohort view with slicers for dynamic filtering.
A21: Q4 | B21: 4
A22: 2019 | B22: 19
A23: Q1 | B23: 5
A24: Q2 | B24: 5
A25: Q3 | B25: 3
A26: Q4 | B26: 6
A27: 2020 | B27: 18
A28: Q1 | B28: 7
A29: Q2 | B29: 2
A30: Q3 | B30: 6
A31: Q4 | B31: 3
A32: 2021 | B32: 13
A33: Q1 | B33: 5
A34: Q2 | B34: 2
A35: Q3 | B35: 4
A36: Q4 | B36: 2
A37: 2022 | B37: 14
A38: Q1 | B38: 6
A39: Q2 | B39: 5
A40: Q3 | B40: 2
A41: Q4 | B41: 1
A42: 2023 | B42: 4
...

Sheet Employee–Project Mapping 
A1: Corrected Employee ID | B1: Employee Name | C1: Employee First Working Day | D1: Corrected Employee First Working Day | E1: Designation | F1: Team | G1: Type | H1: Year of Joining Date | I1: Quarter of Joining Date | J1: Quarter & Year of Joining Date | K1: Project Code | L1: Start Date | M1: End Date | N1: Active Project Count | O1: Over Allocation | Q1: Overallocated Employees
A2: emp062 | B2: Tanya Bose | C2: 43810 | D2: 43810 | E2: Consultant | F2: Support | G2: FTE | H2: 2019 | I2: Q4 | J2: 2019-Q4 | K2: PRJ-024 | L2: =_xlfn.XLOOKUP(K2, Projects!$A:$A, Projects!$D:$D) -> 45160 | M2: =_xlfn.XLOOKUP(K2, Projects!$A:$A, Projects!$F:$F) -> 45991 | N2: =COUNTIFS(A:A,A2, L:L,"<="&M2, M:M,">="&L2) -> 2 | O2: =IF(N2>2,"Overallocated","OK") -> OK | Q2: Emp ID | R2: Emp Name
A3: emp094 | B3: Naina Sethi | C3: 44506 | D3: 44506 | E3: Analyst | F3: Support | G3: FTE | H3: 2021 | I3: Q4 | J3: 2021-Q4 | K3: PRJ-024 | L3: =_xlfn.XLOOKUP(K3, Projects!$A:$A, Projects!$D:$D) -> 45160 | M3: =_xlfn.XLOOKUP(K3, Projects!$A:$A, Projects!$F:$F) -> 45991 | N3: =COUNTIFS(A:A,A3, L:L,"<="&M3, M:M,">="&L3) -> 2 | O3: =IF(N3>2,"Overallocated","OK") -> OK | Q3: {=_xlfn.UNIQUE(_xlfn._xlws.FILTER(CHOOSE({1,2}, A2:A200, B2:B200), O2:O200="Overallocated"))} -> emp085 | R3: Manav Kapoor
A4: emp060 | B4: Ritu Agarwal | C4: 44361 | D4: 44361 | E4: Analyst | F4: Design | G4: FTE | H4: 2021 | I4: Q2 | J4: 2021-Q2 | K4: PRJ-018 | L4: =_xlfn.XLOOKUP(K4, Projects!$A:$A, Projects!$D:$D) -> 45407 | M4: =_xlfn.XLOOKUP(K4, Projects!$A:$A, Projects!$F:$F) -> 46081 | N4: =COUNTIFS(A:A,A4, L:L,"<="&M4, M:M,">="&L4) -> 2 | O4: =IF(N4>2,"Overallocated","OK") -> OK | Q4: emp005 | R4: Neha Malhotra
A5: emp078 | B5: Aishwarya Kulkarni | C5: 44733 | D5: 44733 | E5: Analyst | F5: Design | G5: Intern | H5: 2022 | I5: Q2 | J5: 2022-Q2 | K5: PRJ-018 | L5: =_xlfn.XLOOKUP(K5, Projects!$A:$A, Projects!$D:$D) -> 45407 | M5: =_xlfn.XLOOKUP(K5, Projects!$A:$A, Projects!$F:$F) -> 46081 | N5: =COUNTIFS(A:A,A5, L:L,"<="&M5, M:M,">="&L5) -> 1 | O5: =IF(N5>2,"Overallocated","OK") -> OK | Q5: emp063 | R5: Aditya Kapoor
A6: emp074 | B6: Meera Joshi | C6: 44385 | D6: 44385 | E6: Analyst | F6: Support | G6: FTE | H6: 2021 | I6: Q3 | J6: 2021-Q3 | K6: PRJ-008 | L6: =_xlfn.XLOOKUP(K6, Projects!$A:$A, Projects!$D:$D) -> 45425 | M6: =_xlfn.XLOOKUP(K6, Projects!$A:$A, Projects!$F:$F) -> 46188 | N6: =COUNTIFS(A:A,A6, L:L,"<="&M6, M:M,">="&L6) -> 2 | O6: =IF(N6>2,"Overallocated","OK") -> OK | Q6: emp015 | R6: Nitin Arora
A7: emp085 | B7: Manav Kapoor | C7: 42713 | D7: 42713 | E7: Sr Consultant | F7: QA | G7: FTE | H7: 2016 | I7: Q4 | J7: 2016-Q4 | K7: PRJ-008 | L7: =_xlfn.XLOOKUP(K7, Projects!$A:$A, Projects!$D:$D) -> 45425 | M7: =_xlfn.XLOOKUP(K7, Projects!$A:$A, Projects!$F:$F) -> 46188 | N7: =COUNTIFS(A:A,A7, L:L,"<="&M7, M:M,">="&L7) -> 3 | O7: =IF(N7>2,"Overallocated","OK") -> Overallocated | Q7: emp036 | R7: Meenal Kulkarni
A8: emp100 | B8: Juhi Kapoor | C8: 44774 | D8: 44774 | E8: Analyst | F8: QA | G8: Intern | H8: 2022 | I8: Q3 | J8: 2022-Q3 | K8: PRJ-008 | L8: =_xlfn.XLOOKUP(K8, Projects!$A:$A, Projects!$D:$D) -> 45425 | M8: =_xlfn.XLOOKUP(K8, Projects!$A:$A, Projects!$F:$F) -> 46188 | N8: =COUNTIFS(A:A,A8, L:L,"<="&M8, M:M,">="&L8) -> 1 | O8: =IF(N8>2,"Overallocated","OK") -> OK | Q8: emp123 | R8: Srishti Jain
